16-12-30 17:39:55 homeassistant.components.sensor: Error while setting up platform hp_ilo
Traceback (most recent call last):
  File "/srv/homeassistant/lib/python3.4/site-packages/homeassistant/helpers/entity_component.py", line 150, in _async_setup_platform
    entity_platform.add_entities, discovery_info
  File "/usr/lib/python3.4/asyncio/futures.py", line 388, in __iter__
    yield self  # This tells Task to wait for completion.
  File "/usr/lib/python3.4/asyncio/tasks.py", line 286, in _wakeup
    value = future.result()
  File "/usr/lib/python3.4/asyncio/futures.py", line 277, in result
    raise self._exception
  File "/usr/lib/python3.4/concurrent/futures/thread.py", line 54, in run
    result = self.fn(*self.args, **self.kwargs)
  File "/srv/homeassistant/lib/python3.4/site-packages/homeassistant/components/sensor/hp_ilo.py", line 79, in setup_platform
    client_name=name)
  File "/srv/homeassistant/lib/python3.4/site-packages/homeassistant/components/sensor/hp_ilo.py", line 98, in __init__
    self.update()
  File "/srv/homeassistant/lib/python3.4/site-packages/homeassistant/components/sensor/hp_ilo.py", line 123, in update
    ilo_data = getattr(self.hp_ilo_data.data, self._ilo_function)()
  File "/home/homeassistant/.homeassistant/deps/hpilo.py", line 1275, in get_server_power_on_time
    return self._info_tag('SERVER_INFO', 'GET_SERVER_POWER_ON_TIME', 'SERVER_POWER_ON_MINUTES', process=lambda data: int(data['value']))
  File "/home/homeassistant/.homeassistant/deps/hpilo.py", line 726, in _info_tag
    header, message = self._request(root)
  File "/home/homeassistant/.homeassistant/deps/hpilo.py", line 271, in _request
    message = self._parse_message(data)
  File "/home/homeassistant/.homeassistant/deps/hpilo.py", line 611, in _parse_message
    raise IloError(message, status)
hpilo.IloError: Syntax error: Line #0: syntax error near "" in the line: "". You may have tried to use a feature this iLO version or firmware version does not support.
16-12-30 17:39:59 homeassistant.components.media_player.webostv: No TV found in configuration file or with discovery
16-12-30 17:40:21 netdisco.ssdp: Found malformed XML at http://192.168.2.103:49153/description1.xml: 
16-12-30 17:40:22 netdisco.ssdp: Found malformed XML at http://192.168.2.103:49153/description2.xml: 
16-12-30 17:40:22 netdisco.ssdp: Found malformed XML at http://192.168.2.103:49153/description5.xml: 
16-12-30 17:40:22 netdisco.ssdp: Found malformed XML at http://192.168.2.103:49153/description3.xml: 
16-12-30 17:56:39 homeassistant.core: Error doing job: Future exception was never retrieved
Traceback (most recent call last):
  File "/usr/lib/python3.4/concurrent/futures/thread.py", line 54, in run
    result = self.fn(*self.args, **self.kwargs)
  File "/srv/homeassistant/lib/python3.4/site-packages/homeassistant/core.py", line 1054, in execute_service
    service_handler.func(service_call)
  File "/srv/homeassistant/lib/python3.4/site-packages/homeassistant/components/media_player/__init__.py", line 324, in media_player_service_handler
    getattr(player, method)()
  File "/srv/homeassistant/lib/python3.4/site-packages/homeassistant/components/media_player/cast.py", line 302, in media_next_track
    self.cast.media_controller.skip()
  File "/home/homeassistant/.homeassistant/deps/pychromecast/controllers/media.py", line 359, in skip
    self.seek(int(self.status.duration)-5)
TypeError: int() argument must be a string or a number, not 'NoneType'
16-12-30 17:56:40 homeassistant.core: Error doing job: Future exception was never retrieved
Traceback (most recent call last):
  File "/usr/lib/python3.4/concurrent/futures/thread.py", line 54, in run
    result = self.fn(*self.args, **self.kwargs)
  File "/srv/homeassistant/lib/python3.4/site-packages/homeassistant/core.py", line 1054, in execute_service
    service_handler.func(service_call)
  File "/srv/homeassistant/lib/python3.4/site-packages/homeassistant/components/media_player/__init__.py", line 324, in media_player_service_handler
    getattr(player, method)()
  File "/srv/homeassistant/lib/python3.4/site-packages/homeassistant/components/media_player/cast.py", line 302, in media_next_track
    self.cast.media_controller.skip()
  File "/home/homeassistant/.homeassistant/deps/pychromecast/controllers/media.py", line 359, in skip
    self.seek(int(self.status.duration)-5)
TypeError: int() argument must be a string or a number, not 'NoneType'
16-12-30 18:15:01 pychromecast.socket_client: Heartbeat timeout, resetting connection
16-12-30 18:15:19 pychromecast.socket_client: Failed to connect, retrying in 5.000000s
Traceback (most recent call last):
  File "/home/homeassistant/.homeassistant/deps/pychromecast/socket_client.py", line 239, in initialize_connection
    self.socket.connect((self.host, self.port))
  File "/usr/lib/python3.4/ssl.py", line 840, in connect
    self._real_connect(addr, False)
  File "/usr/lib/python3.4/ssl.py", line 827, in _real_connect
    socket.connect(self, addr)
OSError: [Errno 113] No route to host
16-12-30 18:39:59 homeassistant.components.updater: Got unexpected response: None
16-12-30 19:02:06 homeassistant.core: Error doing job: Future exception was never retrieved
Traceback (most recent call last):
  File "/usr/lib/python3.4/concurrent/futures/thread.py", line 54, in run
    result = self.fn(*self.args, **self.kwargs)
  File "/srv/homeassistant/lib/python3.4/site-packages/homeassistant/core.py", line 1054, in execute_service
    service_handler.func(service_call)
  File "/srv/homeassistant/lib/python3.4/site-packages/homeassistant/components/media_player/__init__.py", line 324, in media_player_service_handler
    getattr(player, method)()
  File "/srv/homeassistant/lib/python3.4/site-packages/homeassistant/components/media_player/cast.py", line 274, in turn_off
    self.cast.quit_app()
  File "/home/homeassistant/.homeassistant/deps/pychromecast/__init__.py", line 346, in quit_app
    self.socket_client.receiver_controller.stop_app()
  File "/home/homeassistant/.homeassistant/deps/pychromecast/socket_client.py", line 833, in stop_app
    inc_session_id=True, wait_for_response=block_till_stopped)
  File "/home/homeassistant/.homeassistant/deps/pychromecast/controllers/__init__.py", line 84, in send_message
    self.namespace, data, inc_session_id, wait_for_response)
  File "/home/homeassistant/.homeassistant/deps/pychromecast/socket_client.py", line 580, in send_platform_message
    inc_session_id, wait_for_response)
  File "/home/homeassistant/.homeassistant/deps/pychromecast/socket_client.py", line 528, in send_message
    self._ensure_channel_connected(destination_id)
  File "/home/homeassistant/.homeassistant/deps/pychromecast/socket_client.py", line 617, in _ensure_channel_connected
    no_add_request_id=True)
  File "/home/homeassistant/.homeassistant/deps/pychromecast/socket_client.py", line 564, in send_message
    raise NotConnected("Chromecast is connecting...")
pychromecast.error.NotConnected: Chromecast is connecting...
16-12-30 22:56:33 pychromecast.socket_client: Heartbeat timeout, resetting connection
